Workbook

Sheet Sheet1
A3: Row Labels
A4: Access
A5: Billing
A6: Hardware
A7: Network
A8: Software
A9: Grand Total

Sheet Cleaned_Data
A1: ticket_id | B1: created_date | C1: resolved_date | D1: priority | E1: category | F1: team | G1: agent | H1: status | I1: customer_satisfaction | J1: sla_target_hours | K1: resolution_hours | L1: sla_met
A2: TCK-10001 | B2: 2024-09-05 15:53:23 | C2: 2024-09-05 21:43:34 | D2: P2 | E2: Access | F2: L2 Support | G2: Emily Watson | H2: Resolved | I2: 5 | J2: 8 | K2: 5.84 | L2: 1
A3: TCK-10002 | B3: 2024-08-17 15:47:20 | C3: 2024-08-17 22:14:42 | D3: P3 | E3: Network | F3: L2 Support | G3: Emily Watson | H3: Resolved | I3: 5 | J3: 24 | K3: 6.46 | L3: 1
A4: TCK-10003 | B4: 2024-07-30 23:13:21 | C4: 2024-07-31 10:14:37 | D4: P3 | E4: Software | F4: Infrastructure | G4: Alex Mercer | H4: Closed | I4: 4 | J4: 24 | K4: 11.02 | L4: 1
A5: TCK-10004 | B5: 2024-03-24 22:52:10 | C5: 2024-03-29 09:46:41 | D5: P4 | E5: Software | F5: L1 Support | G5: Jim Halpert | H5: Resolved | I5: 3 | J5: 48 | K5: 106.91 | L5: 0
A6: TCK-10005 | B6: 2024-10-10 17:35:35 | C6: 2024-10-12 23:44:23 | D6: P3 | E6: Network | F6: Application Support | G6: Sarah Connor | H6: Closed | I6: 3 | J6: 24 | K6: 54.15 | L6: 0
A7: TCK-10006 | B7: 2024-08-12 13:18:43 | D7: P2 | E7: Network | F7: L2 Support | G7: Michael Scott | H7: Escalated | J7: 8
A8: TCK-10007 | B8: 2024-11-28 12:08:20 | C8: 2024-11-28 15:27:22 | D8: P2 | E8: Network | F8: Infrastructure | G8: Dwight Schrute | H8: Closed | I8: 4 | J8: 8 | K8: 3.32 | L8: 1
A9: TCK-10008 | B9: 2024-04-14 00:24:49 | C9: 2024-04-14 07:48:27 | D9: P3 | E9: Hardware | F9: L1 Support | G9: Anita Sharma | H9: Closed | I9: 4 | J9: 24 | K9: 7.39 | L9: 1
A10: TCK-10009 | B10: 2024-04-15 04:05:45 | C10: 2024-04-20 07:07:45 | D10: P4 | E10: Billing | F10: Billing Operations | G10: Emily Watson | H10: Closed | I10: 1 | J10: 48 | K10: 123.03 | L10: 0
A11: TCK-10010 | B11: 2024-01-13 19:11:45 | D11: P4 | E11: Software | F11: L1 Support | G11: Emily Watson | H11: Open | J11: 48
A12: TCK-10011 | B12: 2024-08-08 14:30:04 | C12: 2024-08-09 01:07:48 | D12: P4 | E12: Software | F12: Application Support | G12: Jim Halpert | H12: Closed | I12: 4 | J12: 48 | K12: 10.63 | L12: 1
A13: TCK-10012 | B13: 2024-10-16 15:48:02 | C13: 2024-10-16 22:40:28 | D13: P3 | E13: Software | F13: Billing Operations | G13: Jim Halpert | H13: Closed | I13: 5 | J13: 24 | K13: 6.87 | L13: 1
A14: TCK-10013 | B14: 2024-07-17 05:07:45 | C14: 2024-07-17 16:08:28 | D14: P3 | E14: Software | F14: L1 Support | G14: John Doe | H14: Closed | I14: 3 | J14: 24 | K14: 11.01 | L14: 1
A15: TCK-10014 | B15: 2024-05-28 12:56:58 | C15: 2024-05-29 06:03:07 | D15: P3 | E15: Software | F15: Infrastructure | G15: Ravi Patel | H15: Closed | I15: 5 | J15: 24 | K15: 17.1 | L15: 1
A16: TCK-10015 | B16: 2024-07-27 20:55:34 | C16: 2024-07-27 23:23:32 | D16: P3 | E16: Access | F16: Infrastructure | G16: Sarah Connor | H16: Resolved | I16: 5 | J16: 24 | K16: 2.47 | L16: 1
A17: TCK-10016 | B17: 2024-10-06 19:54:36 | D17: P2 | E17: Software | F17: L2 Support | G17: Ravi Patel | H17: Open | J17: 8
A18: TCK-10017 | B18: 2024-12-04 09:49:16 | C18: 2024-12-04 15:31:00 | D18: P3 | E18: Access | F18: Billing Operations | G18: Anita Sharma | H18: Resolved | I18: 5 | J18: 24 | K18: 5.7 | L18: 1
A19: TCK-10018 | B19: 2024-12-24 13:42:31 | C19: 2024-12-27 08:01:58 | D19: P3 | E19: Network | F19: Infrastructure | G19: Dwight Schrute | H19: Resolved | I19: 3 | J19: 24 | K19: 66.32 | L19: 0
A20: TCK-10019 | B20: 2024-04-29 18:14:21 | C20: 2024-04-29 19:30:35 | D20: P2 | E20: Software | F20: Billing Operations | G20: Sarah Connor | H20: Resolved | I20: 5 | J20: 8 | K20: 1.27 | L20: 1
A21: TCK-10020 | B21: 2024-10-24 18:05:39 | C21: 2024-10-25 09:05:42 | D21: P2 | E21: Hardware | F21: Billing Operations | G21: John Doe | H21: Resolved | I21: 1 | J21: 8 | K21: 15 | L21: 0
A22: TCK-10021 | B22: 2024-07-28 18:36:13 | D22: P3 | E22: Hardware | F22: Infrastructure | G22: Jim Halpert | H22: Escalated | J22: 24
A23: TCK-10022 | B23: 2024-09-09 17:18:09 | C23: 2024-09-09 20:07:53 | D23: P3 | E23: Access | F23: Application Support | G23: Sarah Connor | H23: Resolved | I23: 5 | J23: 24 | K23: 2.83 | L23: 1
A24: TCK-10023 | B24: 2024-08-16 20:39:33 | C24: 2024-08-16 23:42:21 | D24: P2 | E24: Network | F24: L1 Support | G24: Emily Watson | H24: Resolved | I24: 5 | J24: 8 | K24: 3.05 | L24: 1
A25: TCK-10024 | B25: 2024-04-18 11:35:46 | D25: P3 | E25: Access | F25: L2 Support | G25: Priya Nair | H25: Open | J25: 24
A26: TCK-10025 | B26: 2024-08-10 02:30:26 | C26: 2024-08-10 13:42:02 | D26: P3 | E26: Software | F26: Application Support | G26: Jim Halpert | H26: Resolved | I26: 4 | J26: 24 | K26: 11.19 | L26: 1
A27: TCK-10026 | B27: 2024-06-30 16:59:07 | C27: 2024-07-02 08:56:29 | D27: P4 | E27: Network | F27: L1 Support | G27: Alex Mercer | H27: Resolved | I27: 4 | J27: 48 | K27: 39.96 | L27: 1
A28: TCK-10027 | B28: 2024-03-15 04:52:31 | C28: 2024-03-16 09:36:11 | D28: P3 | E28: Access | F28: L2 Support | G28: Michael Scott | H28: Resolved | I28: 3 | J28: 24 | K28: 28.73 | L28: 0
A29: TCK-10028 | B29: 2024-11-28 18:11:22 | D29: P3 | E29: Network | F29: Billing Operations | G29: Alex Mercer | H29: Escalated | J29: 24
A30: TCK-10029 | B30: 2024-12-26 02:21:57 | C30: 2024-12-28 21:48:00 | D30: P3 | E30: Software | F30: Application Support | G30: Dwight Schrute | H30: Resolved | I30: 1 | J30: 24 | K30: 67.43 | L30: 0
A31: TCK-10030 | B31: 2024-01-02 04:05:22 | D31: P4 | E31: Access | F31: Application Support | G31: Michael Scott | H31: Open | J31: 48
A32: TCK-10031 | B32: 2024-10-06 08:03:01 | C32: 2024-10-07 01:42:32 | D32: P3 | E32: Network | F32: L2 Support | G32: Alex Mercer | H32: Closed | I32: 3 | J32: 24 | K32: 17.66 | L32: 1
A33: TCK-10032 | B33: 2024-08-15 04:55:47 | C33: 2024-08-16 00:41:49 | D33: P3 | E33: Billing | F33: Billing Operations | G33: John Doe | H33: Resolved | I33: 3 | J33: 24 | K33: 19.77 | L33: 1
A34: TCK-10033 | B34: 2024-01-27 17:26:28 | C34: 2024-01-28 08:28:35 | D34: P3 | E34: Software | F34: L1 Support | G34: Anita Sharma | H34: Resolved | I34: 4 | J34: 24 | K34: 15.04 | L34: 1
A35: TCK-10034 | B35: 2024-08-15 00:13:12 | C35: 2024-08-15 08:02:18 | D35: P3 | E35: Access | F35: Infrastructure | G35: Emily Watson | H35: Closed | I35: 4 | J35: 24 | K35: 7.82 | L35: 1
A36: TCK-10035 | B36: 2024-09-08 00:30:12 | C36: 2024-09-09 00:26:32 | D36: P2 | E36: Software | F36: L1 Support | G36: Alex Mercer | H36: Resolved | I36: 1 | J36: 8 | K36: 23.94 | L36: 0
A37: TCK-10036 | B37: 2024-03-24 02:44:31 | C37: 2024-03-24 08:21:35 | D37: P3 | E37: Network | F37: Infrastructure | G37: Sarah Connor | H37: Closed | I37: 5 | J37: 24 | K37: 5.62 | L37: 1
A38: TCK-10037 | B38: 2024-09-30 13:28:02 | C38: 2024-09-30 20:36:11 | D38: P2 | E38: Billing | F38: Billing Operations | G38: Alex Mercer | H38: Closed | I38: 4 | J38: 8 | K38: 7.14 | L38: 1
A39: TCK-10038 | B39: 2024-12-07 08:44:11 | C39: 2024-12-07 13:38:57 | D39: P2 | E39: Network | F39: L1 Support | G39: Priya Nair | H39: Closed | I39: 5 | J39: 8 | K39: 4.91 | L39: 1
A40: TCK-10039 | B40: 2024-03-20 09:39:52 | C40: 2024-03-21 13:14:30 | D40: P3 | E40: Access | F40: Billing Operations | G40: Dwight Schrute | H40: Resolved | I40: 2 | J40: 24 | K40: 27.58 | L40: 0
...

Sheet Calc
A1: ticket_id | B1: created_date | C1: resolved_date | D1: priority | E1: category | F1: team | G1: status | H1: resolution_hours | I1: SLA_Met | J1: sla_target_hours | K1: month | L1: breach_hours
A2: TCK-10001 | B2: 2024-09-05 15:53:23 | C2: 2024-09-05 21:43:34 | D2: P2 | E2: Access | F2: L2 Support | G2: Resolved | H2: =Cleaned_Data!K2 -> 5.84 | I2: =IF(OR(G2="Resolved", G2="Closed"), IF(AND(H2<>"", H2<=J2), "YES", "NO"), "") -> YES | J2: =Cleaned_Data!J2 -> 8 | K2: =LEFT(B2, 7) -> 2024-09 | L2: =IF(I2="NO", H2-J2, 0) -> 0
A3: TCK-10002 | B3: 2024-08-17 15:47:20 | C3: 2024-08-17 22:14:42 | D3: P3 | E3: Network | F3: L2 Support | G3: Resolved | H3: =Cleaned_Data!K3 -> 6.46 | I3: =IF(OR(G3="Resolved", G3="Closed"), IF(AND(H3<>"", H3<=J3), "YES", "NO"), "") -> YES | J3: =Cleaned_Data!J3 -> 24 | K3: =LEFT(B3, 7) -> 2024-08 | L3: =IF(I3="NO", H3-J3, 0) -> 0
A4: TCK-10003 | B4: 2024-07-30 23:13:21 | C4: 2024-07-31 10:14:37 | D4: P3 | E4: Software | F4: Infrastructure | G4: Closed | H4: =Cleaned_Data!K4 -> 11.02 | I4: =IF(OR(G4="Resolved", G4="Closed"), IF(AND(H4<>"", H4<=J4), "YES", "NO"), "") -> YES | J4: =Cleaned_Data!J4 -> 24 | K4: =LEFT(B4, 7) -> 2024-07 | L4: =IF(I4="NO", H4-J4, 0) -> 0
A5: TCK-10004 | B5: 2024-03-24 22:52:10 | C5: 2024-03-29 09:46:41 | D5: P4 | E5: Software | F5: L1 Support | G5: Resolved | H5: =Cleaned_Data!K5 -> 106.91 | I5: =IF(OR(G5="Resolved", G5="Closed"), IF(AND(H5<>"", H5<=J5), "YES", "NO"), "") -> NO | J5: =Cleaned_Data!J5 -> 48 | K5: =LEFT(B5, 7) -> 2024-03 | L5: =IF(I5="NO", H5-J5, 0) -> 58.91
A6: TCK-10005 | B6: 2024-10-10 17:35:35 | C6: 2024-10-12 23:44:23 | D6: P3 | E6: Network | F6: Application Support | G6: Closed | H6: =Cleaned_Data!K6 -> 54.15 | I6: =IF(OR(G6="Resolved", G6="Closed"), IF(AND(H6<>"", H6<=J6), "YES", "NO"), "") -> NO | J6: =Cleaned_Data!J6 -> 24 | K6: =LEFT(B6, 7) -> 2024-10 | L6: =IF(I6="NO", H6-J6, 0) -> 30.15
A7: TCK-10006 | B7: 2024-08-12 13:18:43 | D7: P2 | E7: Network | F7: L2 Support | G7: Escalated | H7: =Cleaned_Data!K7 -> 0 | I7: =IF(OR(G7="Resolved", G7="Closed"), IF(AND(H7<>"", H7<=J7), "YES", "NO"), "") | J7: =Cleaned_Data!J7 -> 8 | K7: =LEFT(B7, 7) -> 2024-08 | L7: =IF(I7="NO", H7-J7, 0) -> 0
A8: TCK-10007 | B8: 2024-11-28 12:08:20 | C8: 2024-11-28 15:27:22 | D8: P2 | E8: Network | F8: Infrastructure | G8: Closed | H8: =Cleaned_Data!K8 -> 3.32 | I8: =IF(OR(G8="Resolved", G8="Closed"), IF(AND(H8<>"", H8<=J8), "YES", "NO"), "") -> YES | J8: =Cleaned_Data!J8 -> 8 | K8: =LEFT(B8, 7) -> 2024-11 | L8: =IF(I8="NO", H8-J8, 0) -> 0
A9: TCK-10008 | B9: 2024-04-14 00:24:49 | C9: 2024-04-14 07:48:27 | D9: P3 | E9: Hardware | F9: L1 Support | G9: Closed | H9: =Cleaned_Data!K9 -> 7.39 | I9: =IF(OR(G9="Resolved", G9="Closed"), IF(AND(H9<>"", H9<=J9), "YES", "NO"), "") -> YES | J9: =Cleaned_Data!J9 -> 24 | K9: =LEFT(B9, 7) -> 2024-04 | L9: =IF(I9="NO", H9-J9, 0) -> 0
A10: TCK-10009 | B10: 2024-04-15 04:05:45 | C10: 2024-04-20 07:07:45 | D10: P4 | E10: Billing | F10: Billing Operations | G10: Closed | H10: =Cleaned_Data!K10 -> 123.03 | I10: =IF(OR(G10="Resolved", G10="Closed"), IF(AND(H10<>"", H10<=J10), "YES", "NO"), "") -> NO | J10: =Cleaned_Data!J10 -> 48 | K10: =LEFT(B10, 7) -> 2024-04 | L10: =IF(I10="NO", H10-J10, 0) -> 75.03
A11: TCK-10010 | B11: 2024-01-13 19:11:45 | D11: P4 | E11: Software | F11: L1 Support | G11: Open | H11: =Cleaned_Data!K11 -> 0 | I11: =IF(OR(G11="Resolved", G11="Closed"), IF(AND(H11<>"", H11<=J11), "YES", "NO"), "") | J11: =Cleaned_Data!J11 -> 48 | K11: =LEFT(B11, 7) -> 2024-01 | L11: =IF(I11="NO", H11-J11, 0) -> 0
A12: TCK-10011 | B12: 2024-08-08 14:30:04 | C12: 2024-08-09 01:07:48 | D12: P4 | E12: Software | F12: Application Support | G12: Closed | H12: =Cleaned_Data!K12 -> 10.63 | I12: =IF(OR(G12="Resolved", G12="Closed"), IF(AND(H12<>"", H12<=J12), "YES", "NO"), "") -> YES | J12: =Cleaned_Data!J12 -> 48 | K12: =LEFT(B12, 7) -> 2024-08 | L12: =IF(I12="NO", H12-J12, 0) -> 0
A13: TCK-10012 | B13: 2024-10-16 15:48:02 | C13: 2024-10-16 22:40:28 | D13: P3 | E13: Software | F13: Billing Operations | G13: Closed | H13: =Cleaned_Data!K13 -> 6.87 | I13: =IF(OR(G13="Resolved", G13="Closed"), IF(AND(H13<>"", H13<=J13), "YES", "NO"), "") -> YES | J13: =Cleaned_Data!J13 -> 24 | K13: =LEFT(B13, 7) -> 2024-10 | L13: =IF(I13="NO", H13-J13, 0) -> 0
A14: TCK-10013 | B14: 2024-07-17 05:07:45 | C14: 2024-07-17 16:08:28 | D14: P3 | E14: Software | F14: L1 Support | G14: Closed | H14: =Cleaned_Data!K14 -> 11.01 | I14: =IF(OR(G14="Resolved", G14="Closed"), IF(AND(H14<>"", H14<=J14), "YES", "NO"), "") -> YES | J14: =Cleaned_Data!J14 -> 24 | K14: =LEFT(B14, 7) -> 2024-07 | L14: =IF(I14="NO", H14-J14, 0) -> 0
A15: TCK-10014 | B15: 2024-05-28 12:56:58 | C15: 2024-05-29 06:03:07 | D15: P3 | E15: Software | F15: Infrastructure | G15: Closed | H15: =Cleaned_Data!K15 -> 17.1 | I15: =IF(OR(G15="Resolved", G15="Closed"), IF(AND(H15<>"", H15<=J15), "YES", "NO"), "") -> YES | J15: =Cleaned_Data!J15 -> 24 | K15: =LEFT(B15, 7) -> 2024-05 | L15: =IF(I15="NO", H15-J15, 0) -> 0
A16: TCK-10015 | B16: 2024-07-27 20:55:34 | C16: 2024-07-27 23:23:32 | D16: P3 | E16: Access | F16: Infrastructure | G16: Resolved | H16: =Cleaned_Data!K16 -> 2.47 | I16: =IF(OR(G16="Resolved", G16="Closed"), IF(AND(H16<>"", H16<=J16), "YES", "NO"), "") -> YES | J16: =Cleaned_Data!J16 -> 24 | K16: =LEFT(B16, 7) -> 2024-07 | L16: =IF(I16="NO", H16-J16, 0) -> 0
A17: TCK-10016 | B17: 2024-10-06 19:54:36 | D17: P2 | E17: Software | F17: L2 Support | G17: Open | H17: =Cleaned_Data!K17 -> 0 | I17: =IF(OR(G17="Resolved", G17="Closed"), IF(AND(H17<>"", H17<=J17), "YES", "NO"), "") | J17: =Cleaned_Data!J17 -> 8 | K17: =LEFT(B17, 7) -> 2024-10 | L17: =IF(I17="NO", H17-J17, 0) -> 0
A18: TCK-10017 | B18: 2024-12-04 09:49:16 | C18: 2024-12-04 15:31:00 | D18: P3 | E18: Access | F18: Billing Operations | G18: Resolved | H18: =Cleaned_Data!K18 -> 5.7 | I18: =IF(OR(G18="Resolved", G18="Closed"), IF(AND(H18<>"", H18<=J18), "YES", "NO"), "") -> YES | J18: =Cleaned_Data!J18 -> 24 | K18: =LEFT(B18, 7) -> 2024-12 | L18: =IF(I18="NO", H18-J18, 0) -> 0
A19: TCK-10018 | B19: 2024-12-24 13:42:31 | C19: 2024-12-27 08:01:58 | D19: P3 | E19: Network | F19: Infrastructure | G19: Resolved | H19: =Cleaned_Data!K19 -> 66.32 | I19: =IF(OR(G19="Resolved", G19="Closed"), IF(AND(H19<>"", H19<=J19), "YES", "NO"), "") -> NO | J19: =Cleaned_Data!J19 -> 24 | K19: =LEFT(B19, 7) -> 2024-12 | L19: =IF(I19="NO", H19-J19, 0) -> 42.32
A20: TCK-10019 | B20: 2024-04-29 18:14:21 | C20: 2024-04-29 19:30:35 | D20: P2 | E20: Software | F20: Billing Operations | G20: Resolved | H20: =Cleaned_Data!K20 -> 1.27 | I20: =IF(OR(G20="Resolved", G20="Closed"), IF(AND(H20<>"", H20<=J20), "YES", "NO"), "") -> YES | J20: =Cleaned_Data!J20 -> 8 | K20: =LEFT(B20, 7) -> 2024-04 | L20: =IF(I20="NO", H20-J20, 0) -> 0
A21: TCK-10020 | B21: 2024-10-24 18:05:39 | C21: 2024-10-25 09:05:42 | D21: P2 | E21: Hardware | F21: Billing Operations | G21: Resolved | H21: =Cleaned_Data!K21 -> 15 | I21: =IF(OR(G21="Resolved", G21="Closed"), IF(AND(H21<>"", H21<=J21), "YES", "NO"), "") -> NO | J21: =Cleaned_Data!J21 -> 8 | K21: =LEFT(B21, 7) -> 2024-10 | L21: =IF(I21="NO", H21-J21, 0) -> 7
A22: TCK-10021 | B22: 2024-07-28 18:36:13 | D22: P3 | E22: Hardware | F22: Infrastructure | G22: Escalated | H22: =Cleaned_Data!K22 -> 0 | I22: =IF(OR(G22="Resolved", G22="Closed"), IF(AND(H22<>"", H22<=J22), "YES", "NO"), "") | J22: =Cleaned_Data!J22 -> 24 | K22: =LEFT(B22, 7) -> 2024-07 | L22: =IF(I22="NO", H22-J22, 0) -> 0
A23: TCK-10022 | B23: 2024-09-09 17:18:09 | C23: 2024-09-09 20:07:53 | D23: P3 | E23: Access | F23: Application Support | G23: Resolved | H23: =Cleaned_Data!K23 -> 2.83 | I23: =IF(OR(G23="Resolved", G23="Closed"), IF(AND(H23<>"", H23<=J23), "YES", "NO"), "") -> YES | J23: =Cleaned_Data!J23 -> 24 | K23: =LEFT(B23, 7) -> 2024-09 | L23: =IF(I23="NO", H23-J23, 0) -> 0
A24: TCK-10023 | B24: 2024-08-16 20:39:33 | C24: 2024-08-16 23:42:21 | D24: P2 | E24: Network | F24: L1 Support | G24: Resolved | H24: =Cleaned_Data!K24 -> 3.05 | I24: =IF(OR(G24="Resolved", G24="Closed"), IF(AND(H24<>"", H24<=J24), "YES", "NO"), "") -> YES | J24: =Cleaned_Data!J24 -> 8 | K24: =LEFT(B24, 7) -> 2024-08 | L24: =IF(I24="NO", H24-J24, 0) -> 0
A25: TCK-10024 | B25: 2024-04-18 11:35:46 | D25: P3 | E25: Access | F25: L2 Support | G25: Open | H25: =Cleaned_Data!K25 -> 0 | I25: =IF(OR(G25="Resolved", G25="Closed"), IF(AND(H25<>"", H25<=J25), "YES", "NO"), "") | J25: =Cleaned_Data!J25 -> 24 | K25: =LEFT(B25, 7) -> 2024-04 | L25: =IF(I25="NO", H25-J25, 0) -> 0
A26: TCK-10025 | B26: 2024-08-10 02:30:26 | C26: 2024-08-10 13:42:02 | D26: P3 | E26: Software | F26: Application Support | G26: Resolved | H26: =Cleaned_Data!K26 -> 11.19 | I26: =IF(OR(G26="Resolved", G26="Closed"), IF(AND(H26<>"", H26<=J26), "YES", "NO"), "") -> YES | J26: =Cleaned_Data!J26 -> 24 | K26: =LEFT(B26, 7) -> 2024-08 | L26: =IF(I26="NO", H26-J26, 0) -> 0
A27: TCK-10026 | B27: 2024-06-30 16:59:07 | C27: 2024-07-02 08:56:29 | D27: P4 | E27: Network | F27: L1 Support | G27: Resolved | H27: =Cleaned_Data!K27 -> 39.96 | I27: =IF(OR(G27="Resolved", G27="Closed"), IF(AND(H27<>"", H27<=J27), "YES", "NO"), "") -> YES | J27: =Cleaned_Data!J27 -> 48 | K27: =LEFT(B27, 7) -> 2024-06 | L27: =IF(I27="NO", H27-J27, 0) -> 0
A28: TCK-10027 | B28: 2024-03-15 04:52:31 | C28: 2024-03-16 09:36:11 | D28: P3 | E28: Access | F28: L2 Support | G28: Resolved | H28: =Cleaned_Data!K28 -> 28.73 | I28: =IF(OR(G28="Resolved", G28="Closed"), IF(AND(H28<>"", H28<=J28), "YES", "NO"), "") -> NO | J28: =Cleaned_Data!J28 -> 24 | K28: =LEFT(B28, 7) -> 2024-03 | L28: =IF(I28="NO", H28-J28, 0) -> 4.73
A29: TCK-10028 | B29: 2024-11-28 18:11:22 | D29: P3 | E29: Network | F29: Billing Operations | G29: Escalated | H29: =Cleaned_Data!K29 -> 0 | I29: =IF(OR(G29="Resolved", G29="Closed"), IF(AND(H29<>"", H29<=J29), "YES", "NO"), "") | J29: =Cleaned_Data!J29 -> 24 | K29: =LEFT(B29, 7) -> 2024-11 | L29: =IF(I29="NO", H29-J29, 0) -> 0
A30: TCK-10029 | B30: 2024-12-26 02:21:57 | C30: 2024-12-28 21:48:00 | D30: P3 | E30: Software | F30: Application Support | G30: Resolved | H30: =Cleaned_Data!K30 -> 67.43 | I30: =IF(OR(G30="Resolved", G30="Closed"), IF(AND(H30<>"", H30<=J30), "YES", "NO"), "") -> NO | J30: =Cleaned_Data!J30 -> 24 | K30: =LEFT(B30, 7) -> 2024-12 | L30: =IF(I30="NO", H30-J30, 0) -> 43.43
A31: TCK-10030 | B31: 2024-01-02 04:05:22 | D31: P4 | E31: Access | F31: Application Support | G31: Open | H31: =Cleaned_Data!K31 -> 0 | I31: =IF(OR(G31="Resolved", G31="Closed"), IF(AND(H31<>"", H31<=J31), "YES", "NO"), "") | J31: =Cleaned_Data!J31 -> 48 | K31: =LEFT(B31, 7) -> 2024-01 | L31: =IF(I31="NO", H31-J31, 0) -> 0
A32: TCK-10031 | B32: 2024-10-06 08:03:01 | C32: 2024-10-07 01:42:32 | D32: P3 | E32: Network | F32: L2 Support | G32: Closed | H32: =Cleaned_Data!K32 -> 17.66 | I32: =IF(OR(G32="Resolved", G32="Closed"), IF(AND(H32<>"", H32<=J32), "YES", "NO"), "") -> YES | J32: =Cleaned_Data!J32 -> 24 | K32: =LEFT(B32, 7) -> 2024-10 | L32: =IF(I32="NO", H32-J32, 0) -> 0
A33: TCK-10032 | B33: 2024-08-15 04:55:47 | C33: 2024-08-16 00:41:49 | D33: P3 | E33: Billing | F33: Billing Operations | G33: Resolved | H33: =Cleaned_Data!K33 -> 19.77 | I33: =IF(OR(G33="Resolved", G33="Closed"), IF(AND(H33<>"", H33<=J33), "YES", "NO"), "") -> YES | J33: =Cleaned_Data!J33 -> 24 | K33: =LEFT(B33, 7) -> 2024-08 | L33: =IF(I33="NO", H33-J33, 0) -> 0
A34: TCK-10033 | B34: 2024-01-27 17:26:28 | C34: 2024-01-28 08:28:35 | D34: P3 | E34: Software | F34: L1 Support | G34: Resolved | H34: =Cleaned_Data!K34 -> 15.04 | I34: =IF(OR(G34="Resolved", G34="Closed"), IF(AND(H34<>"", H34<=J34), "YES", "NO"), "") -> YES | J34: =Cleaned_Data!J34 -> 24 | K34: =LEFT(B34, 7) -> 2024-01 | L34: =IF(I34="NO", H34-J34, 0) -> 0
A35: TCK-10034 | B35: 2024-08-15 00:13:12 | C35: 2024-08-15 08:02:18 | D35: P3 | E35: Access | F35: Infrastructure | G35: Closed | H35: =Cleaned_Data!K35 -> 7.82 | I35: =IF(OR(G35="Resolved", G35="Closed"), IF(AND(H35<>"", H35<=J35), "YES", "NO"), "") -> YES | J35: =Cleaned_Data!J35 -> 24 | K35: =LEFT(B35, 7) -> 2024-08 | L35: =IF(I35="NO", H35-J35, 0) -> 0
A36: TCK-10035 | B36: 2024-09-08 00:30:12 | C36: 2024-09-09 00:26:32 | D36: P2 | E36: Software | F36: L1 Support | G36: Resolved | H36: =Cleaned_Data!K36 -> 23.94 | I36: =IF(OR(G36="Resolved", G36="Closed"), IF(AND(H36<>"", H36<=J36), "YES", "NO"), "") -> NO | J36: =Cleaned_Data!J36 -> 8 | K36: =LEFT(B36, 7) -> 2024-09 | L36: =IF(I36="NO", H36-J36, 0) -> 15.94
A37: TCK-10036 | B37: 2024-03-24 02:44:31 | C37: 2024-03-24 08:21:35 | D37: P3 | E37: Network | F37: Infrastructure | G37: Closed | H37: =Cleaned_Data!K37 -> 5.62 | I37: =IF(OR(G37="Resolved", G37="Closed"), IF(AND(H37<>"", H37<=J37), "YES", "NO"), "") -> YES | J37: =Cleaned_Data!J37 -> 24 | K37: =LEFT(B37, 7) -> 2024-03 | L37: =IF(I37="NO", H37-J37, 0) -> 0
A38: TCK-10037 | B38: 2024-09-30 13:28:02 | C38: 2024-09-30 20:36:11 | D38: P2 | E38: Billing | F38: Billing Operations | G38: Closed | H38: =Cleaned_Data!K38 -> 7.14 | I38: =IF(OR(G38="Resolved", G38="Closed"), IF(AND(H38<>"", H38<=J38), "YES", "NO"), "") -> YES | J38: =Cleaned_Data!J38 -> 8 | K38: =LEFT(B38, 7) -> 2024-09 | L38: =IF(I38="NO", H38-J38, 0) -> 0
A39: TCK-10038 | B39: 2024-12-07 08:44:11 | C39: 2024-12-07 13:38:57 | D39: P2 | E39: Network | F39: L1 Support | G39: Closed | H39: =Cleaned_Data!K39 -> 4.91 | I39: =IF(OR(G39="Resolved", G39="Closed"), IF(AND(H39<>"", H39<=J39), "YES", "NO"), "") -> YES | J39: =Cleaned_Data!J39 -> 8 | K39: =LEFT(B39, 7) -> 2024-12 | L39: =IF(I39="NO", H39-J39, 0) -> 0
A40: TCK-10039 | B40: 2024-03-20 09:39:52 | C40: 2024-03-21 13:14:30 | D40: P3 | E40: Access | F40: Billing Operations | G40: Resolved | H40: =Cleaned_Data!K40 -> 27.58 | I40: =IF(OR(G40="Resolved", G40="Closed"), IF(AND(H40<>"", H40<=J40), "YES", "NO"), "") -> NO | J40: =Cleaned_Data!J40 -> 24 | K40: =LEFT(B40, 7) -> 2024-03 | L40: =IF(I40="NO", H40-J40, 0) -> 3.58
...

Sheet KPI_Summary
B2: Service Desk SLA & KPI Summary
B3: Automated Operational Metrics (Full Year 2024)
B5: Total Ticket Volume | E5: Overall SLA Compliance % | H5: Avg Resolution Time (Hrs)
B6: =COUNTA(Cleaned_Data!A2:A5001) -> 5000 | E6: =COUNTIFS(Calc!I2:I5001, "YES") / (COUNTIFS(Cleaned_Data!H2:H5001, "Resolved") + COUNTIFS(Cleaned_Data!H2:H5001, "Closed")) -> 0.81771068 | H6: =AVERAGE(Calc!H2:H5001) -> 18.06401
B9: Open Backlog Count | E9: Avg Customer CSAT (1-5) | H9: Total Breached Tickets
B10: =COUNTIFS(Cleaned_Data!H2:H5001, "Open") + COUNTIFS(Cleaned_Data!H2:H5001, "Escalated") -> 562 | E10: =AVERAGE(Cleaned_Data!I2:I5001) -> 4.0018026 | H10: =COUNTIFS(Calc!I2:I5001, "NO") -> 809

Sheet Monthly_Trend
B2: Monthly SLA Compliance & Ticket Volume Trend
B4: Month | C4: Total Intake Volume | D4: Resolved Tickets | E4: Tickets Met SLA | F4: SLA Compliance % | G4: Avg Resolution Hrs
B5: 2024-01 | C5: =COUNTIFS(Calc!K$2:K$5001, B5) -> 408 | D5: =COUNTIFS(Calc!K$2:K$5001, B5, Cleaned_Data!H$2:H$5001, "Resolved") + COUNTIFS(Calc!K$2:K$5001, B5, Cleaned_Data!H$2:H$5001, "Closed") -> 362 | E5: =COUNTIFS(Calc!K$2:K$5001, B5, Calc!I$2:I$5001, "YES") -> 306 | F5: =IFERROR(E5/D5, 0) -> 0.84530387 | G5: =IFERROR(AVERAGEIFS(Calc!H$2:H$5001, Calc!K$2:K$5001, B5), 0) -> 15.556176
B6: 2024-02 | C6: =COUNTIFS(Calc!K$2:K$5001, B6) -> 419 | D6: =COUNTIFS(Calc!K$2:K$5001, B6, Cleaned_Data!H$2:H$5001, "Resolved") + COUNTIFS(Calc!K$2:K$5001, B6, Cleaned_Data!H$2:H$5001, "Closed") -> 382 | E6: =COUNTIFS(Calc!K$2:K$5001, B6, Calc!I$2:I$5001, "YES") -> 303 | F6: =IFERROR(E6/D6, 0) -> 0.79319372 | G6: =IFERROR(AVERAGEIFS(Calc!H$2:H$5001, Calc!K$2:K$5001, B6), 0) -> 16.649284
B7: 2024-03 | C7: =COUNTIFS(Calc!K$2:K$5001, B7) -> 420 | D7: =COUNTIFS(Calc!K$2:K$5001, B7, Cleaned_Data!H$2:H$5001, "Resolved") + COUNTIFS(Calc!K$2:K$5001, B7, Cleaned_Data!H$2:H$5001, "Closed") -> 376 | E7: =COUNTIFS(Calc!K$2:K$5001, B7, Calc!I$2:I$5001, "YES") -> 303 | F7: =IFERROR(E7/D7, 0) -> 0.80585106 | G7: =IFERROR(AVERAGEIFS(Calc!H$2:H$5001, Calc!K$2:K$5001, B7), 0) -> 21.683214
B8: 2024-04 | C8: =COUNTIFS(Calc!K$2:K$5001, B8) -> 405 | D8: =COUNTIFS(Calc!K$2:K$5001, B8, Cleaned_Data!H$2:H$5001, "Resolved") + COUNTIFS(Calc!K$2:K$5001, B8, Cleaned_Data!H$2:H$5001, "Closed") -> 356 | E8: =COUNTIFS(Calc!K$2:K$5001, B8, Calc!I$2:I$5001, "YES") -> 303 | F8: =IFERROR(E8/D8, 0) -> 0.8511236 | G8: =IFERROR(AVERAGEIFS(Calc!H$2:H$5001, Calc!K$2:K$5001, B8), 0) -> 14.74837
B9: 2024-05 | C9: =COUNTIFS(Calc!K$2:K$5001, B9) -> 417 | D9: =COUNTIFS(Calc!K$2:K$5001, B9, Cleaned_Data!H$2:H$5001, "Resolved") + COUNTIFS(Calc!K$2:K$5001, B9, Cleaned_Data!H$2:H$5001, "Closed") -> 370 | E9: =COUNTIFS(Calc!K$2:K$5001, B9, Calc!I$2:I$5001, "YES") -> 302 | F9: =IFERROR(E9/D9, 0) -> 0.81621622 | G9: =IFERROR(AVERAGEIFS(Calc!H$2:H$5001, Calc!K$2:K$5001, B9), 0) -> 18.801894
B10: 2024-06 | C10: =COUNTIFS(Calc!K$2:K$5001, B10) -> 425 | D10: =COUNTIFS(Calc!K$2:K$5001, B10, Cleaned_Data!H$2:H$5001, "Resolved") + COUNTIFS(Calc!K$2:K$5001, B10, Cleaned_Data!H$2:H$5001, "Closed") -> 377 | E10: =COUNTIFS(Calc!K$2:K$5001, B10, Calc!I$2:I$5001, "YES") -> 311 | F10: =IFERROR(E10/D10, 0) -> 0.82493369 | G10: =IFERROR(AVERAGEIFS(Calc!H$2:H$5001, Calc!K$2:K$5001, B10), 0) -> 19.370094
B11: 2024-07 | C11: =COUNTIFS(Calc!K$2:K$5001, B11) -> 427 | D11: =COUNTIFS(Calc!K$2:K$5001, B11, Cleaned_Data!H$2:H$5001, "Resolved") + COUNTIFS(Calc!K$2:K$5001, B11, Cleaned_Data!H$2:H$5001, "Closed") -> 372 | E11: =COUNTIFS(Calc!K$2:K$5001, B11, Calc!I$2:I$5001, "YES") -> 303 | F11: =IFERROR(E11/D11, 0) -> 0.81451613 | G11: =IFERROR(AVERAGEIFS(Calc!H$2:H$5001, Calc!K$2:K$5001, B11), 0) -> 16.1774
B12: 2024-08 | C12: =COUNTIFS(Calc!K$2:K$5001, B12) -> 443 | D12: =COUNTIFS(Calc!K$2:K$5001, B12, Cleaned_Data!H$2:H$5001, "Resolved") + COUNTIFS(Calc!K$2:K$5001, B12, Cleaned_Data!H$2:H$5001, "Closed") -> 397 | E12: =COUNTIFS(Calc!K$2:K$5001, B12, Calc!I$2:I$5001, "YES") -> 345 | F12: =IFERROR(E12/D12, 0) -> 0.86901763 | G12: =IFERROR(AVERAGEIFS(Calc!H$2:H$5001, Calc!K$2:K$5001, B12), 0) -> 14.984424
B13: 2024-09 | C13: =COUNTIFS(Calc!K$2:K$5001, B13) -> 388 | D13: =COUNTIFS(Calc!K$2:K$5001, B13, Cleaned_Data!H$2:H$5001, "Resolved") + COUNTIFS(Calc!K$2:K$5001, B13, Cleaned_Data!H$2:H$5001, "Closed") -> 332 | E13: =COUNTIFS(Calc!K$2:K$5001, B13, Calc!I$2:I$5001, "YES") -> 275 | F13: =IFERROR(E13/D13, 0) -> 0.82831325 | G13: =IFERROR(AVERAGEIFS(Calc!H$2:H$5001, Calc!K$2:K$5001, B13), 0) -> 15.797835
B14: 2024-10 | C14: =COUNTIFS(Calc!K$2:K$5001, B14) -> 412 | D14: =COUNTIFS(Calc!K$2:K$5001, B14, Cleaned_Data!H$2:H$5001, "Resolved") + COUNTIFS(Calc!K$2:K$5001, B14, Cleaned_Data!H$2:H$5001, "Closed") -> 371 | E14: =COUNTIFS(Calc!K$2:K$5001, B14, Calc!I$2:I$5001, "YES") -> 292 | F14: =IFERROR(E14/D14, 0) -> 0.78706199 | G14: =IFERROR(AVERAGEIFS(Calc!H$2:H$5001, Calc!K$2:K$5001, B14), 0) -> 23.075291
B15: 2024-11 | C15: =COUNTIFS(Calc!K$2:K$5001, B15) -> 422 | D15: =COUNTIFS(Calc!K$2:K$5001, B15, Cleaned_Data!H$2:H$5001, "Resolved") + COUNTIFS(Calc!K$2:K$5001, B15, Cleaned_Data!H$2:H$5001, "Closed") -> 382 | E15: =COUNTIFS(Calc!K$2:K$5001, B15, Calc!I$2:I$5001, "YES") -> 305 | F15: =IFERROR(E15/D15, 0) -> 0.79842932 | G15: =IFERROR(AVERAGEIFS(Calc!H$2:H$5001, Calc!K$2:K$5001, B15), 0) -> 18.313294
B16: 2024-12 | C16: =COUNTIFS(Calc!K$2:K$5001, B16) -> 414 | D16: =COUNTIFS(Calc!K$2:K$5001, B16, Cleaned_Data!H$2:H$5001, "Resolved") + COUNTIFS(Calc!K$2:K$5001, B16, Cleaned_Data!H$2:H$5001, "Closed") -> 361 | E16: =COUNTIFS(Calc!K$2:K$5001, B16, Calc!I$2:I$5001, "YES") -> 281 | F16: =IFERROR(E16/D16, 0) -> 0.77839335 | G16: =IFERROR(AVERAGEIFS(Calc!H$2:H$5001, Calc!K$2:K$5001, B16), 0) -> 21.579034

Sheet Priority_Category
B2: SLA Performance by Priority & Category
B4: Performance by Priority Level
B5: Priority | C5: SLA Target (Hrs) | D5: Total Tickets | E5: Resolved Tickets | F5: SLA Met | G5: SLA Compliance % | H5: Avg Res Hrs
B6: P1 | C6: 4 | D6: =COUNTIFS(Cleaned_Data!D$2:D$5001, B6) -> 482 | E6: =COUNTIFS(Cleaned_Data!D$2:D$5001, B6, Cleaned_Data!H$2:H$5001, "Resolved") + COUNTIFS(Cleaned_Data!D$2:D$5001, B6, Cleaned_Data!H$2:H$5001, "Closed") -> 433 | F6: =COUNTIFS(Cleaned_Data!D$2:D$5001, B6, Calc!I$2:I$5001, "YES") -> 339 | G6: =IFERROR(F6/E6, 0) -> 0.78290993 | H6: =IFERROR(AVERAGEIFS(Calc!H$2:H$5001, Cleaned_Data!D$2:D$5001, B6), 0) -> 4.5240456
B7: P2 | C7: 8 | D7: =COUNTIFS(Cleaned_Data!D$2:D$5001, B7) -> 1271 | E7: =COUNTIFS(Cleaned_Data!D$2:D$5001, B7, Cleaned_Data!H$2:H$5001, "Resolved") + COUNTIFS(Cleaned_Data!D$2:D$5001, B7, Cleaned_Data!H$2:H$5001, "Closed") -> 1130 | F7: =COUNTIFS(Cleaned_Data!D$2:D$5001, B7, Calc!I$2:I$5001, "YES") -> 936 | G7: =IFERROR(F7/E7, 0) -> 0.82831858 | H7: =IFERROR(AVERAGEIFS(Calc!H$2:H$5001, Cleaned_Data!D$2:D$5001, B7), 0) -> 9.3804406
B8: P3 | C8: 24 | D8: =COUNTIFS(Cleaned_Data!D$2:D$5001, B8) -> 2276 | E8: =COUNTIFS(Cleaned_Data!D$2:D$5001, B8, Cleaned_Data!H$2:H$5001, "Resolved") + COUNTIFS(Cleaned_Data!D$2:D$5001, B8, Cleaned_Data!H$2:H$5001, "Closed") -> 2025 | F8: =COUNTIFS(Cleaned_Data!D$2:D$5001, B8, Calc!I$2:I$5001, "YES") -> 1657 | G8: =IFERROR(F8/E8, 0) -> 0.8182716 | H8: =IFERROR(AVERAGEIFS(Calc!H$2:H$5001, Cleaned_Data!D$2:D$5001, B8), 0) -> 17.591586
B9: P4 | C9: 48 | D9: =COUNTIFS(Cleaned_Data!D$2:D$5001, B9) -> 971 | E9: =COUNTIFS(Cleaned_Data!D$2:D$5001, B9, Cleaned_Data!H$2:H$5001, "Resolved") + COUNTIFS(Cleaned_Data!D$2:D$5001, B9, Cleaned_Data!H$2:H$5001, "Closed") -> 850 | F9: =COUNTIFS(Cleaned_Data!D$2:D$5001, B9, Calc!I$2:I$5001, "YES") -> 697 | G9: =IFERROR(F9/E9, 0) -> 0.82 | H9: =IFERROR(AVERAGEIFS(Calc!H$2:H$5001, Cleaned_Data!D$2:D$5001, B9), 0) -> 37.25898
B12: Performance by Service Category
B13: Category | C13: Total Tickets | D13: Resolved Tickets | E13: SLA Met | F13: SLA Compliance % | G13: Avg Res Hrs
B14: Network | C14: =COUNTIFS(Cleaned_Data!E$2:E$5001, B14) -> 946 | D14: =COUNTIFS(Cleaned_Data!E$2:E$5001, B14, Cleaned_Data!H$2:H$5001, "Resolved") + COUNTIFS(Cleaned_Data!E$2:E$5001, B14, Cleaned_Data!H$2:H$5001, "Closed") -> 836 | E14: =COUNTIFS(Cleaned_Data!E$2:E$5001, B14, Calc!I$2:I$5001, "YES") -> 679 | F14: =IFERROR(E14/D14, 0) -> 0.81220096 | G14: =IFERROR(AVERAGEIFS(Calc!H$2:H$5001, Cleaned_Data!E$2:E$5001, B14), 0) -> 18.812146
B15: Software | C15: =COUNTIFS(Cleaned_Data!E$2:E$5001, B15) -> 1732 | D15: =COUNTIFS(Cleaned_Data!E$2:E$5001, B15, Cleaned_Data!H$2:H$5001, "Resolved") + COUNTIFS(Cleaned_Data!E$2:E$5001, B15, Cleaned_Data!H$2:H$5001, "Closed") -> 1531 | E15: =COUNTIFS(Cleaned_Data!E$2:E$5001, B15, Calc!I$2:I$5001, "YES") -> 1241 | F15: =IFERROR(E15/D15, 0) -> 0.81058132 | G15: =IFERROR(AVERAGEIFS(Calc!H$2:H$5001, Cleaned_Data!E$2:E$5001, B15), 0) -> 18.147956
B16: Hardware | C16: =COUNTIFS(Cleaned_Data!E$2:E$5001, B16) -> 760 | D16: =COUNTIFS(Cleaned_Data!E$2:E$5001, B16, Cleaned_Data!H$2:H$5001, "Resolved") + COUNTIFS(Cleaned_Data!E$2:E$5001, B16, Cleaned_Data!H$2:H$5001, "Closed") -> 678 | E16: =COUNTIFS(Cleaned_Data!E$2:E$5001, B16, Calc!I$2:I$5001, "YES") -> 555 | F16: =IFERROR(E16/D16, 0) -> 0.81858407 | G16: =IFERROR(AVERAGEIFS(Calc!H$2:H$5001, Cleaned_Data!E$2:E$5001, B16), 0) -> 18.596592
B17: Access | C17: =COUNTIFS(Cleaned_Data!E$2:E$5001, B17) -> 1027 | D17: =COUNTIFS(Cleaned_Data!E$2:E$5001, B17, Cleaned_Data!H$2:H$5001, "Resolved") + COUNTIFS(Cleaned_Data!E$2:E$5001, B17, Cleaned_Data!H$2:H$5001, "Closed") -> 915 | E17: =COUNTIFS(Cleaned_Data!E$2:E$5001, B17, Calc!I$2:I$5001, "YES") -> 758 | F17: =IFERROR(E17/D17, 0) -> 0.8284153 | G17: =IFERROR(AVERAGEIFS(Calc!H$2:H$5001, Cleaned_Data!E$2:E$5001, B17), 0) -> 17.529094
B18: Billing | C18: =COUNTIFS(Cleaned_Data!E$2:E$5001, B18) -> 535 | D18: =COUNTIFS(Cleaned_Data!E$2:E$5001, B18, Cleaned_Data!H$2:H$5001, "Resolved") + COUNTIFS(Cleaned_Data!E$2:E$5001, B18, Cleaned_Data!H$2:H$5001, "Closed") -> 478 | E18: =COUNTIFS(Cleaned_Data!E$2:E$5001, B18, Calc!I$2:I$5001, "YES") -> 396 | F18: =IFERROR(E18/D18, 0) -> 0.82845188 | G18: =IFERROR(AVERAGEIFS(Calc!H$2:H$5001, Cleaned_Data!E$2:E$5001, B18), 0) -> 16.739645

Sheet Dashboard
B2: EXECUTIVE SERVICE DESK DASHBOARD
B3: Daily / Weekly / Monthly Governance View
B5: Total Tickets | E5: SLA Compliance % | H5: Avg Res Time (Hrs) | K5: Open Backlog
B6: =KPI_Summary!B6 -> 5000 | E6: =KPI_Summary!E6 -> 0.81771068 | H6: =KPI_Summary!H6 -> 18.06401 | K6: =KPI_Summary!B10 -> 562

Sheet Notes
B2: Report Documentation & Metric Definitions
B4: Metric / Concept | C4: Definition & Governance Business Standard | D4: Excel Formula Used
B5: Total Tickets | C5: Count of all support ticket intake records created in 2024. | D5: =COUNTA(Cleaned_Data!A2:A5001) -> 5000
B6: Resolved Tickets | C6: Count of tickets with completed status ('Resolved' or 'Closed'). | D6: =COUNTIFS(Cleaned_Data!H2:H5001, "Resolved") + COUNTIFS(Cleaned_Data!H2:H5001, "Closed") -> 4438
B7: SLA Compliance % | C7: Standard Definition: Tickets Met SLA / Total Resolved Tickets. | D7: =COUNTIFS(Calc!I2:I5001, "YES") / (COUNTIFS(Cleaned_Data!H2:H5001, "Resolved") + COUNTIFS(Cleaned_Data!H2:H5001, "Closed")) -> 0.81771068
B8: Avg Resolution Time | C8: Mean turnaround time (decimal hours) from creation to resolution for resolved tickets. | D8: =AVERAGE(Calc!H2:H5001) -> 18.06401
B9: Open Backlog | C9: Count of active tickets currently in 'Open' or 'Escalated' status. | D9: =COUNTIFS(Cleaned_Data!H2:H5001, "Open") + COUNTIFS(Cleaned_Data!H2:H5001, "Escalated") -> 562
B10: Avg CSAT | C10: Average customer satisfaction rating on a 1-5 scale for resolved tickets. | D10: =AVERAGE(Cleaned_Data!I2:I5001) -> 4.0018026
B11: SLA Target (P1) | C11: Critical Incident Target = 4 Hours. | D11: Hardcoded SLA Target Rule
B12: SLA Target (P2) | C12: High Priority Target = 8 Hours. | D12: Hardcoded SLA Target Rule
B13: SLA Target (P3) | C13: Medium Priority Target = 24 Hours. | D13: Hardcoded SLA Target Rule
B14: SLA Target (P4) | C14: Low Priority Target = 48 Hours. | D14: Hardcoded SLA Target Rule
B15: Conditional Formatting | C15: Green: SLA >= 90% | Amber: 80% <= SLA < 90% | Red: SLA < 80% | D15: Excel CellIsRule Conditional Formatting on merged E6:G7
